Workbook

Sheet Read Me
A1: Read Me
A2: Literature matrix for: Burnout, Sleep, and Physiological Recovery in Women (working women and students)
A4: What this is
A5: Sheets | B5: Literature Matrix = one row per source (41). Summary = automatic counts by year, design, variables, and devices, plus the research gap.
A6: Order | B6: Rows follow the reference numbers in the literature review (AMA: numbered in order of first citation).
A7: Sources | B7: All 41 sources are from 2021–2026 and were checked in PubMed (title, authors, year, DOI). The WHO ICD-11 entry is a web source.
A8: Where details come from | B8: The abstract of each paper. For Gilin 2023, Calderón-García 2024, Alzueta 2022, Garcia-Ceja 2026, Hirten 2021, and Oluwadiya 2024, some details were confirmed in the open-access full text.
A9: Key
A10: Y | B10: Yes, the study measured or reported this. Blank = no.
A11: NR | B11: Not reported in the abstract. Check the full text if you need it.
A12: n/a (review) | B12: Reviews pool many studies, so a single % women does not apply.
A13: * after a country | B13: Country of the authors' institution; the abstract does not state where data were collected.
A14: — | B14: Not measured / not applicable.
A15: Women (%) | B15: Share of women in the sample, stored as a number so you can sort and filter it.
A16: Consumer wearable | B16: Commercial device such as Fitbit, Apple Watch, Oura, WHOOP, Garmin, Polar, or Huawei. Research actigraphs and 24-h ECG are not counted.
A17: Women / sex results | B17: The study is women-only or reports results separately for women or by sex.
A18: How to use it
A19: Filter | B19: Use the arrows in row 4 of the Literature Matrix. Example: filter “Students” = Y to see the student studies.
A20: Find the gap | B20: Filter Burnout, Sleep, HRV / RHR, and Consumer wearable all to Y. Very few studies remain, and none report results for women.
A21: Relevance column | B21: These are suggestions. Edit them so they match your own reasoning about each study.
A22: Links | B22: PMID cells open PubMed; DOI cells open the article.

Sheet Literature Matrix
A1: Literature Matrix: Burnout, Sleep, and Physiological Recovery in Women
A2: 41 sources (2021–2026), numbered as in the literature review. Filter any column with the arrows in row 4. See the Read Me sheet for the key.
A3: Study | F3: Sample and design | L3: Variables and measures | P3: Findings and appraisal | T3: Coverage (Y = yes) | Z3: Source
A4: Ref # | B4: First author | C4: Year | D4: Title | E4: Journal | F4: Country / setting | G4: Population | H4: Sample size (n) | I4: Women (%) | J4: Study design | K4: Design type | L4: Burnout / stress measure | M4: Sleep measure | N4: Recovery measure (HRV, RHR, scores) | O4: Wearable device | P4: Key findings | Q4: Limitations | R4: Relevance to my study | S4: Used in review section(s) | T4: Burnout measured | U4: Sleep measured | V4: HRV / RHR measured | W4: Consumer wearable | X4: Women / sex results | Y4: Students | Z4: PMID | AA4: DOI | AB4: AMA reference
A5: 1 | B5: World Health Organization | C5: 2024 | D5: QD85 Burnout. In: ICD-11 for Mortality and Morbidity Statistics. Version 2024-01 | E5: ICD-11 (online) | F5: International | G5: Not applicable (classification) | H5: — | I5: n/a | J5: International classification entry (ICD-11 code QD85) | K5: Other | L5: Defines burnout (3 dimensions) | M5: — | N5: — | O5: — | P5: Burnout = syndrome from chronic workplace stress that has not been successfully managed. 3 dimensions: exhaustion; mental distance from the job (cynicism); reduced professional efficacy. Listed under factors influencing health status, not as a medical condition. | Q5: Refers only to the occupational context, so it does not cover students. | R5: Definition for the introduction; reason to use “academic burnout” for students. | S5: Introduction | Z5: — | AA5: https://icd.who.int/browse/2024-01/mms/en#129180281 | AB5: World Health Organization. QD85 Burnout. In: ICD-11 for Mortality and Morbidity Statistics. Version 2024-01. Accessed October 7, 2026. https://icd.who.int/browse/2024-01/mms/en#129180281
A6: 2 | B6: Gómez-Urquiza et al | C6: 2023 | D6: Prevalence and levels of burnout in nursing students: a systematic review with meta-analysis | E6: Nurse Educ Pract | F6: Multiple (review) | G6: Nursing students | H6: 34 studies reviewed; 15 pooled (n = 2744) | I6: n/a (review) | J6: Systematic review and meta-analysis | K6: Review | L6: Burnout and its dimensions (emotional exhaustion, depersonalization, personal accomplishment) | M6: — | N6: — | O6: — | P6: Burnout prevalence 19% (95% CI 11%–28%). High emotional exhaustion 41%, low personal accomplishment 27%, high depersonalization 25%. | Q6: Fewer than half of the reviewed studies could be pooled; nursing students only; estimate lower than Hernández-Mariano 2024 (35%). | R6: Shows burnout is common in students; emotional exhaustion is the main problem. | S6: Introduction; Students | T6: Y | Y6: Y | Z6: 37651959 | AA6: 10.1016/j.nepr.2023.103753 | AB6: Gómez-Urquiza JL, Velando-Soriano A, Membrive-Jiménez MJ, et al. Prevalence and levels of burnout in nursing students: a systematic review with meta-analysis. Nurse Educ Pract. 2023;72:103753. doi:10.1016/j.nepr.2023.103753
A7: 3 | B7: Hernández-Mariano et al | C7: 2024 | D7: Prevalence of academic burnout among nursing students: a systematic review and meta-analysis | E7: J Nurs Educ | F7: Multiple (review); highest prevalence in Asia | G7: Nursing students | H7: 34 studies (n = 9554) | I7: n/a (review) | J7: Systematic review and meta-analysis | K7: Review | L7: Academic burnout (prevalence and dimensions) | M7: — | N7: — | O7: — | P7: Pooled academic burnout 35% (95% CI 24%–47%; 23 studies); highest in Asia (58%). High emotional exhaustion 40%, high depersonalization 23%, low personal accomplishment 30%. | Q7: Nursing students only; estimate differs from Gómez-Urquiza 2023 (19%), possibly because of different scales and cut-offs. | R7: Supports including students; gives a prevalence figure for the introduction. | S7: Introduction; Students | T7: Y | Y7: Y | Z7: 39120506 | AA7: 10.3928/01484834-20240502-04 | AB7: Hernández-Mariano JÁ, Hurtado-Salgado E, Velázquez-Núñez MDC, Cupul-Uicab LA. Prevalence of academic burnout among nursing students: a systematic review and meta-analysis. J Nurs Educ. 2024;63(8):533-539. doi:10.3928/01484834-20240502-04
A8: 4 | B8: Hoff and Lee | C8: 2021 | D8: Burnout and physician gender: what do we know? | E8: Med Care | F8: Review (framed around US physicians) | G8: Physicians (focus on women physicians) | H8: 43 studies (published 2010–2019) | I8: n/a (review) | J8: Systematic review (PRISMA) | K8: Review | L8: Physician burnout (as measured in included studies) | M8: — | N8: — | O8: — | P8: A third or more of both male and female physicians reported burnout. Women generally more likely to have burnout than men, especially emotional exhaustion. | Q8: Included studies from 2010–2019 only; physicians only; no pooled estimate. | R8: Supports focusing on women; points to emotional exhaustion. | S8: Introduction; Women-Specific Considerations | T8: Y | X8: Y | Z8: 34081678 | AA8: 10.1097/mlr.0000000000001584 | AB8: Hoff T, Lee DR. Burnout and physician gender: what do we know? Med Care. 2021;59(8):711-720. doi:10.1097/mlr.0000000000001584
A9: 5 | B9: Membrive-Jiménez et al | C9: 2022 | D9: Relation between burnout and sleep problems in nurses: a systematic review with meta-analysis | E9: Healthcare (Basel) | F9: Multiple (review) | G9: Nurses | H9: 12 studies; meta-analysis n = 1127 | I9: n/a (review) | J9: Systematic review and meta-analysis | K9: Review | L9: Validated burnout scales | M9: Validated sleep scales (sleep problems, insomnia) | N9: — | O9: — | P9: Burnout and sleep problems correlated r = 0.39 (95% CI 0.29–0.48; p < .001), a moderate positive link. Being female was the only sociodemographic factor that affected the link. | Q9: Nurses only; correlations, so direction is unclear; self-reported sleep. | R9: Core evidence that burnout and poor sleep go together; female sex matters. | S9: Burnout and Sleep | T9: Y | U9: Y | X9: Y | Z9: 35628091 | AA9: 10.3390/healthcare10050954 | AB9: Membrive-Jiménez MJ, Gómez-Urquiza JL, Suleiman-Martos N, et al. Relation between burnout and sleep problems in nurses: a systematic review with meta-analysis. Healthcare (Basel). 2022;10(5):954. doi:10.3390/healthcare10050954
A10: 6 | B10: Zakiei et al | C10: 2025 | D10: The mechanism of sleep quality's effect on academic burnout: examining the mediating role of perceived stress | E10: BMC Med Educ | F10: Iran | G10: Medical sciences university students | H10: 476 | I10: 0.664 | J10: Cross-sectional survey (2024) | K10: Cross-sectional | L10: Academic Burnout Inventory; Perceived Stress Scale | M10: Pittsburgh Sleep Quality Index (PSQI) | N10: — | O10: — | P10: Poorer sleep quality linked to more perceived stress and more academic burnout. Part of the sleep–burnout link went through perceived stress (indirect effect β = 0.13). | Q10: Cross-sectional, so cause and effect unclear; one university; self-report only. | R10: Shows the burnout–sleep link in students. | S10: Burnout and Sleep | T10: Y | U10: Y | Y10: Y | Z10: 40624657 | AA10: 10.1186/s12909-025-07617-6 | AB10: Zakiei A, Khazaie H, Azadi M, Mohsenpour S, Komasi S. The mechanism of sleep quality's effect on academic burnout: examining the mediating role of perceived stress. BMC Med Educ. 2025;25(1):1018. doi:10.1186/s12909-025-07617-6
A11: 7 | B11: Höglund et al | C11: 2023 | D11: Risk factors for insomnia and burnout: a longitudinal population-based cohort study | E11: Stress Health | F11: Sweden | G11: General population, ages 18–79 | H11: 1702 (insomnia cohort); 1972 (burnout cohort) | I11: NR | J11: Population-based longitudinal cohort, 3-year follow-up | K11: Longitudinal / cohort | L11: Self-reported burnout | M11: Self-reported insomnia | N11: — | O11: — | P11: Baseline burnout was among the strongest predictors of new insomnia 3 years later (ORs for insomnia across all risk factors 1.62–2.73). ORs generally similar in men and women. | Q11: Self-report only; general population rather than workers or students. | R11: Suggests burnout comes before insomnia (time order). | S11: Burnout and Sleep | T11: Y | U11: Y | X11: Y | Z11: 36634111 | AA11: 10.1002/smi.3218 | AB11: Höglund P, Hakelind C, Nordin M, Nordin S. Risk factors for insomnia and burnout: a longitudinal population-based cohort study. Stress Health. 2023;39(4):798-812. doi:10.1002/smi.3218
A12: 8 | B12: Świtaj et al | C12: 2025 | D12: Insomnia mediates the longitudinal association between loneliness and burnout among nurses | E12: Sci Rep | F12: Poland* | G12: Nurses | H12: 520 | I12: NR | J12: Two-wave longitudinal survey (6 months apart) | K12: Longitudinal / cohort | L12: Maslach Burnout Inventory–General Survey (MBI-GS); De Jong Gierveld Loneliness Scale | M12: Athens Insomnia Scale | N12: — | O12: — | P12: Loneliness linked to more cynicism and lower professional efficacy. Insomnia mediated the links between loneliness and all three burnout dimensions. | Q12: Only two time points; nurses only; self-report. | R12: Sleep problems as a pathway into burnout. | S12: Burnout and Sleep | T12: Y | U12: Y | Z12: 40659822 | AA12: 10.1038/s41598-025-11264-8 | AB12: Świtaj P, Baka Ł, Kapica Ł, Bugajska J, Januszczak J, Sienkiewicz-Jarosz H. Insomnia mediates the longitudinal association between loneliness and burnout among nurses. Sci Rep. 2025;15(1):25384. doi:10.1038/s41598-025-11264-8
A13: 9 | B13: Frick et al | C13: 2025 | D13: The bidirectional relationship between sleep and daily burnout-related experiences: self-report vs actigraphy-derived measures | E13: Sleep Health | F13: Netherlands* | G13: Non-clinical employees | H13: 72 | I13: NR | J13: 7-day experience sampling study | K13: Daily diary / experience sampling | L13: Trait burnout; daily exhaustion, boredom, feeling positively challenged | M13: Actigraphy and self-reported sleep (quality, timing) | N13: — | O13: Research actigraph (not a consumer device) | P13: Poor sleep quality predicted next-day exhaustion and boredom, not the other way round. Later sleep timing linked to feeling more positively challenged. Trait burnout changed several sleep–burnout links. | Q13: One week only; small sample. | R13: Best evidence on direction (sleep → next-day exhaustion) using objective sleep. | S13: Burnout and Sleep; Wearable Device Studies | T13: Y | U13: Y | Z13: 40328567 | AA13: 10.1016/j.sleh.2025.03.007 | AB13: Frick S, Smolders K, van der Meij L, Demerouti E, de Kort Y. The bidirectional relationship between sleep and daily burnout-related experiences: self-report vs actigraphy-derived measures. Sleep Health. 2025;11(3):382-389. doi:10.1016/j.sleh.2025.03.007
A14: 10 | B14: Fang et al | C14: 2021 | D14: Day-to-day variability in sleep parameters and depression risk: a prospective cohort study of training physicians | E14: NPJ Digit Med | F14: USA* | G14: First-year resident physicians (interns) | H14: 2115 | I14: NR | J14: Prospective cohort, 1 year (Intern Health Study) | K14: Longitudinal / cohort | L14: Depression (PHQ-9) and daily mood (smartphone app); no burnout measure | M14: Wearable total sleep time, bedtime, wake time, day-to-day variability | N14: — | O14: Fitbit | P14: Shorter sleep linked to more depression. Within a person, more sleep, earlier bedtime, later wake time and less day-to-day change in sleep → better next-day mood. Sleep variability mattered about as much as average sleep. | Q14: Measured depression and mood, not burnout; doctors in training only. | R14: Sleep consistency matters, not just duration. | S14: Burnout and Sleep; Wearable Device Studies | U14: Y | W14: Y | Z14: 33603132 | AA14: 10.1038/s41746-021-00400-z | AB14: Fang Y, Forger DB, Frank E, Sen S, Goldstein C. Day-to-day variability in sleep parameters and depression risk: a prospective cohort study of training physicians. NPJ Digit Med. 2021;4(1):28. doi:10.1038/s41746-021-00400-z
A15: 11 | B15: Sy et al | C15: 2026 | D15: Longitudinal associations of sleep midpoint and sleep midpoint variability with the mental health of young adult college students | E15: Chronobiol Int | F15: USA* | G15: College students aged 18–26 (two universities) | H15: 256 | I15: NR | J15: Daily diary study, 2 weeks | K15: Daily diary / experience sampling | L15: Depression (PHQ-2), anxiety (GAD-2), stress (PSS-4); no burnout measure | M15: Electronic sleep diary: sleep midpoint and its variability | N15: — | O15: — | P15: Later sleep midpoint linked to more depression, anxiety and stress. More variable sleep midpoint correlated with worse depressive symptoms (r = 0.14). | Q15: Self-reported sleep, no device; 2 weeks; no burnout measure. | R15: Sleep timing and regularity matter for student mental health. | S15: Burnout and Sleep | U15: Y | Y15: Y | Z15: 42138024 | AA15: 10.1080/07420528.2026.2671355 | AB15: Sy JRT, Brombach RK, Leete JJ, et al. Longitudinal associations of sleep midpoint and sleep midpoint variability with the mental health of young adult college students. Chronobiol Int. 2026;43(9):1424-1430. doi:10.1080/07420528.2026.2671355
A16: 12 | B16: Bourassa et al | C16: 2026 | D16: Objective biobehavioral measures reflect burnout states and temporal changes in a nursing population: a prospective observational assessment | E16: Nurs Rep | F16: USA* | G16: Hospital nurses | H16: 50 (45 analysed) | I16: NR | J16: Prospective observational study, 30 days | K16: Longitudinal / cohort | L16: Burnout questionnaire at baseline and day 30 (emotional exhaustion, depersonalization) | M16: Oura sleep measures, including sleep variability | N16: Oura heart rate–based measures | O16: Oura ring | P16: Nurses with burnout had more variable sleep. Sleep measures classified burnout state with 75.75% accuracy. Heart rate measures explained changes in emotional exhaustion and depersonalization over time (R² = 0.13). | Q16: Small and exploratory; 1 month; nurses only. | R16: Closest to my design: consumer wearable + burnout over time. | S16: Burnout and Sleep; Burnout and Physiological Recovery; Wearable Device Studies | T16: Y | U16: Y | V16: Y | W16: Y | Z16: 41591133 | AA16: 10.3390/nursrep16010036 | AB16: Bourassa KA, Lamichhane B, Bartek N, Bautista C, Sano A, Madan A. Objective biobehavioral measures reflect burnout states and temporal changes in a nursing population: a prospective observational assessment. Nurs Rep. 2026;16(1):36. doi:10.3390/nursrep16010036
A17: 13 | B17: Kane et al | C17: 2025 | D17: Continuous heart rate variability monitoring, stress and recovery in doctors: a systematic review and meta-analysis | E17: Occup Med (Lond) | F17: 7 countries (review) | G17: Doctors | H17: 7 studies (12–54 participants each) | I17: n/a (review) | J17: Systematic review and meta-analysis | K17: Review | L17: Stress vs recovery periods (contextual or psychological assessment) | M17: — | N17: Continuous ambulatory HRV (RMSSD, SDNN, LF, LF/HF) | O17: A different HRV device in each study | P17: HRV differed between stress and recovery periods: RMSSD lower (SMD −0.63) and SDNN lower (SMD −1.05) during stress; LF and LF/HF higher. | Q17: Only 7 small studies; quality moderate at best; doctors only. | R17: HRV tracks work stress and recovery, which supports HRV as an outcome. | S17: Burnout and Physiological Recovery; Recovery During Breaks | V17: Y | Z17: 41157926 | AA17: 10.1093/occmed/kqaf101 | AB17: Kane L, Powell D, Martin KR, Rees C, Curran J, Ball D. Continuous heart rate variability monitoring, stress and recovery in doctors: a systematic review and meta-analysis. Occup Med (Lond). 2025;75(9):630-639. doi:10.1093/occmed/kqaf101
A18: 14 | B18: Lee et al | C18: 2026 | D18: Occupational stress in the neuroticism-burnout link: an exploratory examination of physiological contributions | E18: Clin Psychopharmacol Neurosci | F18: South Korea | G18: Workers in high-stress occupations | H18: 150 | I18: NR | J18: Cross-sectional; structural equation modelling | K18: Cross-sectional | L18: Burnout; perceived occupational stress; neuroticism | M18: — | N18: Resting PPG-derived HRV; frontal EEG | O18: Maumgyeol Basic wearable system | P18: Perceived stress strongly predicted burnout. The wearable HRV → burnout path showed only a non-significant negative trend. Older age linked to less burnout. | Q18: Cross-sectional; short resting recording; physiological pathway exploratory. | R18: HRV–burnout link is weak in non-clinical workers. | S18: Burnout and Physiological Recovery | T18: Y | V18: Y | W18: Y | Z18: 42528350 | AA18: 10.9758/cpn.25.1377 | AB18: Lee HS, Lee T, Kwon K, Ahn WS, Lee SH. Occupational stress in the neuroticism-burnout link: an exploratory examination of physiological contributions. Clin Psychopharmacol Neurosci. 2026;24(3):570-579. doi:10.9758/cpn.25.1377
A19: 15 | B19: Turner et al | C19: 2026 | D19: Heart rate variability across recording conditions: associations with depression and burnout in inpatients with stress-related disorders | E19: J Psychosom Res | F19: Switzerland* | G19: Inpatients with clinical burnout plus depression or adjustment disorder | H19: 153 | I19: 0.5751634 | J19: Longitudinal observational (baseline and after up to 8 weeks of treatment) | K19: Longitudinal / cohort | L19: Shirom-Melamed Burnout Measure; Beck Depression Inventory-II | M19: — | N19: HRV supine, standing, post-exercise, and over 24 h | O19: Clinical HRV recordings (device not named in abstract) | P19: Non-linear links between burnout severity and HRV, only in the standing position. Little evidence for a depression–HRV link. After treatment, HRV rose (e.g., RMSSD and SDNN supine; 24-h SDNN). | Q19: Clinical inpatients, not a general population sample. | R19: The HRV–burnout link depends on how and when HRV is recorded. | S19: Burnout and Physiological Recovery; Gaps in the Literature | T19: Y | V19: Y | Z19: 42000525 | AA19: 10.1016/j.jpsychores.2026.112674 | AB19: Turner W, La Marca R, Infanger D, et al. Heart rate variability across recording conditions: associations with depression and burnout in inpatients with stress-related disorders. J Psychosom Res. 2026;207:112674. doi:10.1016/j.jpsychores.2026.112674
A20: 16 | B20: Böckelmann et al | C20: 2026 | D20: Heart rate variability and burnout risk among healthy employees in jobs involving interaction with others | E20: Front Physiol | F20: Germany* | G20: Employees in high-interaction jobs (nursery teachers, bank clerks, medical assistants) | H20: 202 | I20: NR | J20: Cross-sectional | K20: Cross-sectional | L20: Maslach Burnout Inventory–General Survey (MBI-GS) | M20: — | N20: 24-h ECG HRV, plus 6-h daytime and 6-h night-time windows | O20: 24-h ECG (not a consumer device) | P20: HRV differed by burnout risk over 24 h and during the day, but not at night. Correlations with burnout were mostly weak. Effects were mainly driven by age and gender. | Q20: Cross-sectional; only 5.4% had increased burnout risk. | R20: Night-time HRV (what wearables mostly record) showed the weakest link. | S20: Burnout and Physiological Recovery; Gaps in the Literature | T20: Y | V20: Y | X20: Y | Z20: 42614159 | AA20: 10.3389/fphys.2026.1908141 | AB20: Böckelmann I, Hartung J, Darius S, Sammito S, Thielmann B. Heart rate variability and burnout risk among healthy employees in jobs involving interaction with others. Front Physiol. 2026;17:1908141. doi:10.3389/fphys.2026.1908141
A21: 17 | B21: Gilin et al | C21: 2023 | D21: Impact of a wellness leadership intervention on the empathy, burnout, and resting heart rate of medical faculty | E21: Mayo Clin Proc Innov Qual Outcomes | F21: Canada | G21: Medical faculty leaders (80% physicians, 20% basic scientists) | H21: 49 (39 shared Fitbit data) | I21: 0.67 | J21: Wait-list controlled quasi-experiment, 15 weeks (6-week wellness course) | K21: Intervention / quasi-experimental | L21: Weekly burnout and empathy surveys | M21: — | N21: Resting heart rate during sleep | O21: Fitbit Inspire 2 | P21: While waiting for the course, the control group's resting heart rate rose by about 1.4 beats/min and empathy fell; the course group did not show these changes. The course prevented burnout from getting worse. | Q21: Not randomised; small; during COVID-19; 10 of 49 did not share Fitbit data. | R21: Fitbit sleeping heart rate can track stress-related change over weeks. | S21: Burnout and Physiological Recovery; Wearable Device Studies | T21: Y | V21: Y | W21: Y | Z21: 38075429 | AA21: 10.1016/j.mayocpiqo.2023.09.005 | AB21: Gilin DA, Anderson GG, Etezad S, Lee-Baggley D, Cooper AM, Preston RJ. Impact of a wellness leadership intervention on the empathy, burnout, and resting heart rate of medical faculty. Mayo Clin Proc Innov Qual Outcomes. 2023;7(6):545-555. doi:10.1016/j.mayocpiqo.2023.09.005
A22: 18 | B22: Hübner et al | C22: 2022 | D22: Effects of a one-week vacation with various activity programs on well-being, heart rate variability, and sleep quality in healthy vacationers: an open comparative study | E22: BMC Public Health | F22: Austria | G22: Healthy, untrained adults on a 1-week active vacation | H22: 52 | I22: NR | J22: Open comparative pre–post study (golf vs Nordic walking/e-biking) | K22: Intervention / quasi-experimental | L22: Recovery–stress questionnaire (EBF-24); WHO-5 well-being | M22: Sleep quality (EBF-24); sleep architecture from HRV | N22: 24-h ECG HRV (SDNN, pNN50, RMSSD, LF/HF, total power) | O22: 24-h ECG (not a consumer device) | P22: Well-being, sleep quality and HRV improved after the vacation. | Q22: No control group without a vacation; measured only 1 day before and 1 day after. | R22: Breaks can restore sleep and HRV, which is the basis for H3 (recovery during breaks). | S22: Recovery During Breaks; Gaps in the Literature | U22: Y | V22: Y | Z22: 36575415 | AA22: 10.1186/s12889-022-14838-7 | AB22: Hübner M, Lechleitner P, Neumayr G. Effects of a one-week vacation with various activity programs on well-being, heart rate variability, and sleep quality in healthy vacationers: an open comparative study. BMC Public Health. 2022;22(1):2435. doi:10.1186/s12889-022-14838-7
A23: 19 | B23: Chen et al | C23: 2026 | D23: The impact of school life and holidays on sleep and physical activity patterns in junior high school students: a small-sample longitudinal study using wearable devices | E23: Front Public Health | F23: China | G23: First-year middle-school students | H23: 27 (14 boys, 13 girls) | I23: 0.48148148 | J23: Longitudinal, full school year (school days, weekends, winter and summer vacation) | K23: Longitudinal / cohort | L23: None | M23: Sleep onset, wake time, deep/light/REM and total sleep | N23: — | O23: Huawei Band 6 | P23: Only 26.71% met sleep recommendations on school days. Sleep improved during holidays; winter vacation had more total and deep sleep than summer. Girls had longer deep sleep but less physical activity than boys. | Q23: Adolescents; very small sample; no burnout or HRV measure. | R23: Shows a consumer band can track sleep changes between term time and vacations. | S23: Recovery During Breaks | U23: Y | W23: Y | X23: Y | Y23: Y | Z23: 42305752 | AA23: 10.3389/fpubh.2026.1833198 | AB23: Chen Y, Xu K, Zhao Y, et al. The impact of school life and holidays on sleep and physical activity patterns in junior high school students: a small-sample longitudinal study using wearable devices. Front Public Health. 2026;14:1833198. doi:10.3389/fpubh.2026.1833198
A24: 20 | B24: Kazlauskas et al | C24: 2023 | D24: Validation of the Recovery Experience Questionnaire in a Lithuanian healthcare personnel | E24: Int J Environ Res Public Health | F24: Lithuania | G24: Healthcare workers | H24: 471 | I24: NR | J24: Psychometric validation (confirmatory factor analysis) | K24: Measure validation | L24: Recovery Experience Questionnaire (16 items); PHQ-4; WHO-5 | M24: — | N24: — | O24: — | P24: Confirmed 4 recovery factors: psychological detachment, relaxation, mastery, control. Recovery experiences correlated with anxiety, depression and well-being. | Q24: Healthcare workers only; self-report; no physiological data. | R24: Possible extra measure of how participants recover during time off. | S24: Recovery During Breaks | Z24: 36768099 | AA24: 10.3390/ijerph20032734 | AB24: Kazlauskas E, Dumarkaite A, Gelezelyte O, Nomeikaite A, Zelviene P. Validation of the Recovery Experience Questionnaire in a Lithuanian healthcare personnel. Int J Environ Res Public Health. 2023;20(3):2734. doi:10.3390/ijerph20032734
A25: 21 | B25: Oluwadiya et al | C25: 2024 | D25: Evaluating the factor structure, reliability and validity of the Copenhagen Burnout Inventory-Student Survey (CBI-SS) among faculty of arts students of Ekiti State University, Ado-Ekiti, Nigeria | E25: Sci Rep | F25: Nigeria | G25: University students (Ekiti State University) | H25: 635 | I25: NR | J25: Cross-sectional psychometric validation | K25: Measure validation | L25: Copenhagen Burnout Inventory–Student Survey (CBI-SS) | M25: — | N25: — | O25: — | P25: Reliability 0.957 (subscales 0.862–0.914). Four-factor structure fit after removing item 10. Burnout scores were negatively correlated with academic self-efficacy and grade point average. | Q25: One university; one item removed; self-report. | R25: The personal burnout scale is shared with the worker version of the CBI, so one measure can cover students and working women. | S25: Students; Implications for the Proposed Study | T25: Y | Y25: Y | Z25: 38714782 | AA25: 10.1038/s41598-024-61310-0 | AB25: Oluwadiya KS, Owoeye OK, Adeoti AO. Evaluating the factor structure, reliability and validity of the Copenhagen Burnout Inventory-Student Survey (CBI-SS) among faculty of arts students of Ekiti State University, Ado-Ekiti, Nigeria. Sci Rep. 2024;14(1):10476. doi:10.1038/s41598-024-61310-0
A26: 22 | B26: Alawad et al | C26: 2026 | D26: Heart rate variability and autonomic function in health professions students: associations with academic stress and lifestyle factors | E26: Physiol Rep | F26: Sudan* | G26: Health professions students | H26: 237 | I26: 0.814 | J26: Cross-sectional | K26: Cross-sectional | L26: Perceived academic stress | M26: Sleep quality (one of the lifestyle factors) | N26: Resting HRV (time, frequency and Poincaré indices) | O26: Resting recording (device not named in abstract) | P26: 65.0% had normal autonomic function; 35.0% had autonomic imbalance. Academic stress linked to autonomic imbalance in female students (p = 0.013). No links with lifestyle factors, including sleep quality. | Q26: Cross-sectional; one short resting recording; no burnout measure. | R26: Academic stress shows up in HRV, especially in women. | S26: Students | U26: Y | V26: Y | X26: Y | Y26: Y | Z26: 42410881 | AA26: 10.14814/phy2.71012 | AB26: Alawad A, Merghani T, Chowdhury N, Hisham HA. Heart rate variability and autonomic function in health professions students: associations with academic stress and lifestyle factors. Physiol Rep. 2026;14(13):e71012. doi:10.14814/phy2.71012
A27: 23 | B27: Sathyanarayana et al | C27: 2026 | D27: Examining the use of consumer wearable devices and digital tools for stress measurement in college students: scoping review of methods | E27: JMIR Mhealth Uhealth | F27: Multiple (review) | G27: College-aged students | H27: 134 studies (published 2020–2025) | I27: n/a (review) | J27: Scoping review | K27: Review | L27: Psychological stress detection | M27: — | N27: Physiological signals (electrodermal activity most common) | O27: Mostly wrist-worn wearables | P27: Electrodermal activity was the most used signal (57.5%). 62.8% of studies used existing datasets, and about 80% of those used one dataset (WESAD) with only 15 participants. 27.6% did not report sex; only 4 studies justified their sample size. | Q27: Focuses on short-term stress detection and algorithms, not burnout or sleep. | R27: Shows student wearable research is narrow and often ignores sex. | S27: Students | W27: Y | Y27: Y | Z27: 41911361 | AA27: 10.2196/64144 | AB27: Sathyanarayana A, Amin OB, An J, Onnela JP. Examining the use of consumer wearable devices and digital tools for stress measurement in college students: scoping review of methods. JMIR Mhealth Uhealth. 2026;14:e64144. doi:10.2196/64144
A28: 24 | B28: Garcia-Ceja et al | C28: 2026 | D28: A dataset of university students' stress and anxiety levels based on questionnaires and wearable sensors | E28: Sci Data | F28: Mexico | G28: Undergraduates at two universities (computer science, mathematics engineering) | H28: 35 | I28: 0.315 | J28: Public dataset (data descriptor), one semester, Feb–Jul 2025 | K28: Other | L28: Daily self-rated stress and anxiety (mobile app) | M28: Fitbit sleep quality | N28: Fitbit HRV, oxygen saturation, stress score | O28: Fitbit Inspire 3 | P28: Over 80% questionnaire compliance across the semester; validated Fitbit measures included. | Q28: Describes a dataset and does not test hypotheses; stress and anxiety, not burnout; mostly male, technical programmes. | R28: Shows semester-long wearable monitoring of students is feasible. | S28: Students; Wearable Device Studies | U28: Y | V28: Y | W28: Y | Y28: Y | Z28: 41876550 | AA28: 10.1038/s41597-026-07085-7 | AB28: Garcia-Ceja E, Alvarado-Uribe J, Escamilla-Ambrosio PJ, et al. A dataset of university students' stress and anxiety levels based on questionnaires and wearable sensors. Sci Data. 2026;13(1):732. doi:10.1038/s41597-026-07085-7
A29: 25 | B29: Thakur et al | C29: 2025 | D29: Gender disparities and burnout among emergency physicians: a systematic review by the World Academic Council of Emergency Medicine-Female Leadership Academy for Medical Excellence | E29: West J Emerg Med | F29: 10 countries (review) | G29: Emergency physicians | H29: 18 studies (n = 26 939) | I29: n/a (review) | J29: Systematic review (PRISMA) | K29: Review | L29: Maslach Burnout Inventory–Human Services Survey (MBI-HSS) | M29: — | N29: — | O29: — | P29: Overall burnout did not differ by sex, but more women had high emotional exhaustion (69% vs 57%) and low personal accomplishment (45% vs 29%). | Q29: Emergency physicians only; English-language studies; inconsistent reporting across studies. | R29: Women's burnout shows mainly as exhaustion, so the exhaustion dimension matters most. | S29: Women-Specific Considerations | T29: Y | X29: Y | Z29: 40145929 | AA29: 10.5811/westjem.29331 | AB29: Thakur S, Chauhan V, Galwankar S, et al. Gender disparities and burnout among emergency physicians: a systematic review by the World Academic Council of Emergency Medicine-Female Leadership Academy for Medical Excellence. West J Emerg Med. 2025;26(2):338-346. doi:10.5811/westjem.29331
A30: 26 | B30: Calderón-García et al | C30: 2024 | D30: Gender differences in autonomic and psychological stress responses among educators: a heart rate variability and psychological assessment study | E30: Front Psychol | F30: Spain | G30: Teachers (compulsory and university level) | H30: 235 | I30: 0.71914894 | J30: Cross-sectional | K30: Cross-sectional | L30: Stress, anxiety, burnout and personality questionnaires | M30: — | N30: HRV (at least 6 min seated) | O30: Polar V800 heart rate monitor | P30: Women reported more stress and anxiety than men but had higher HRV (stronger parasympathetic activity). | Q30: Cross-sectional; short seated recording; teachers only. | R30: Self-reported stress and HRV may not line up in women. | S30: Women-Specific Considerations | T30: Y | V30: Y | W30: Y | X30: Y | Z30: 39439753 | AA30: 10.3389/fpsyg.2024.1422709 | AB30: Calderón-García A, Álvarez-Gallardo E, Belinchón-deMiguel P, Clemente-Suárez VJ. Gender differences in autonomic and psychological stress responses among educators: a heart rate variability and psychological assessment study. Front Psychol. 2024;15:1422709. doi:10.3389/fpsyg.2024.1422709
A31: 27 | B31: de Jager et al | C31: 2026 | D31: Wearable-derived heart rate variability across the menstrual cycle, hormonal contraceptive use, and reproductive life stages in females: a living systematic review | E31: Sports Med | F31: Multiple (living review) | G31: Females of any age | H31: 16 studies | I31: 1 | J31: Living systematic review | K31: Review | L31: — | M31: — | N31: Wearable- or mobile-measured HRV | O31: Various wearable/mobile devices | P31: HRV higher early in the menstrual cycle and lower toward the end (3%–9% difference). Hormonal contraceptive users had lower HRV, especially late in the cycle. HRV tended to decline after menopause. | Q31: Studies classified cycle phase differently; evidence quality moderate. | R31: Need to record cycle phase and contraceptive use. | S31: Women-Specific Considerations; Gaps in the Literature | V31: Y | W31: Y | X31: Y | Z31: 41545627 | AA31: 10.1007/s40279-025-02388-y | AB31: de Jager E, Caulfield B, Angelidi E, MacNamee B, Holden S. Wearable-derived heart rate variability across the menstrual cycle, hormonal contraceptive use, and reproductive life stages in females: a living systematic review. Sports Med. 2026;56(5):1153-1173. doi:10.1007/s40279-025-02388-y
A32: 28 | B32: Alzueta et al | C32: 2022 | D32: Tracking sleep, temperature, heart rate, and daily symptoms across the menstrual cycle with the Oura Ring in healthy women | E32: Int J Womens Health | F32: USA (California) | G32: Healthy women with regular ovulatory cycles (mean age 24) | H32: 26 | I32: 1 | J32: Longitudinal, across one menstrual cycle | K32: Longitudinal / cohort | L32: Daily diary: mood, readiness, symptoms | M32: Oura sleep continuity and stages; diary sleep quality | N32: Oura heart rate, HRV (RMSSD), skin temperature | O32: Oura ring | P32: Oura sleep measures and perceived sleep did not change across the cycle. Skin temperature and heart rate did change. | Q32: Small; one cycle each; healthy young women only. | R32: Cycle phase affects heart rate more than sleep, so cycle phase should be recorded. | S32: Women-Specific Considerations | U32: Y | V32: Y | W32: Y | X32: Y | Z32: 35422659 | AA32: 10.2147/ijwh.s341917 | AB32: Alzueta E, de Zambotti M, Javitz H, et al. Tracking sleep, temperature, heart rate, and daily symptoms across the menstrual cycle with the Oura Ring in healthy women. Int J Womens Health. 2022;14:491-503. doi:10.2147/ijwh.s341917
A33: 29 | B33: Holmes et al | C33: 2026 | D33: Four core circadian behaviors that improve cardiorespiratory fitness through consistent sleep | E33: Sleep | F33: WHOOP members (country not stated in abstract) | G33: Healthy adult WHOOP users | H33: 38 838 | I33: NR | J33: Pre–post quasi-experiment with matched controls (31-day “Core Four” challenge) | K33: Intervention / quasi-experimental | L33: — | M33: Sleep consistency, duration, duration variability | N33: Resting heart rate, HRV, cardiorespiratory fitness | O33: WHOOP 3.0 and 4.0 | P33: Compared with matched controls, participants improved sleep consistency, resting heart rate and HRV. Better sleep consistency partly explained the gains in fitness and parasympathetic activity. | Q33: Not randomised; authors work for WHOOP; healthy users, no burnout measure. | R33: Links sleep consistency with HRV in a very large wearable sample. | S33: Wearable Device Studies | U33: Y | V33: Y | W33: Y | Z33: 41065723 | AA33: 10.1093/sleep/zsaf318 | AB33: Holmes KE, Kim J, Fielding F, Zeitzer JM, von Hippel W. Four core circadian behaviors that improve cardiorespiratory fitness through consistent sleep. Sleep. 2026;49(2):zsaf318. doi:10.1093/sleep/zsaf318
A34: 30 | B34: Azadifar et al | C34: 2026 | D34: Severity of depression and anxiety symptoms is reflected in physiological and behavioral metrics collected from a consumer-grade wearable ring | E34: BMC Med | F34: Finland | G34: Adults aged 33–35 (Northern Finland Birth Cohort 1986) | H34: 1290 | I34: NR | J34: Cross-sectional (population cohort) | K34: Cross-sectional | L34: Anxiety (GAD-7); depression and anxiety (HSCL-25); no burnout measure | M34: Oura sleep stages (REM, deep, light) | N34: Night-time heart rate and RMSSD | O34: Oura ring (2 weeks) | P34: People with moderate-to-severe anxiety, or with depression and anxiety symptoms, had less REM and deep sleep, more light sleep, higher night-time heart rate, lower RMSSD and less daytime activity. | Q34: Cross-sectional; one age group; depression and anxiety, not burnout. | R34: Shows nightly Oura heart rate and RMSSD differ with mental health symptoms. | S34: Wearable Device Studies | U34: Y | V34: Y | W34: Y | Z34: 42811329 | AA34: 10.1186/s12916-026-05276-y | AB34: Azadifar S, Sameh A, Nauha L, Kärmeniemi M, Niemelä M, Farrahi V. Severity of depression and anxiety symptoms is reflected in physiological and behavioral metrics collected from a consumer-grade wearable ring. BMC Med. 2026;24(1):532. doi:10.1186/s12916-026-05276-y
A35: 31 | B35: Perrone et al | C35: 2025 | D35: Physiologic readiness and subjective workload of performing operations: a prospective observational study of attending and trainee surgeons | E35: Am J Surg | F35: USA* | G35: Surgeons (29 attendings, 37 trainees) | H35: 66 | I35: NR | J35: Prospective observational | K35: Longitudinal / cohort | L35: Self-rated workload of operations | M35: — | N35: HRV-based recovery score | O35: Wearable biometric sensor (brand not named in abstract) | P35: Recovery score was not linked to perceived workload in trainees or attendings. Junior surgeons had higher recovery scores than senior surgeons. Trainees' self-ratings differed by gender. | Q35: Surgeons only; measured workload, not burnout. | R35: Recovery scores are not shown to reflect stress, so raw HRV and RHR are better main outcomes. | S35: Wearable Device Studies; Gaps in the Literature | V35: Y | W35: Y | X35: Y | Z35: 39788069 | AA35: 10.1016/j.amjsurg.2024.116175 | AB35: Perrone K, Earley M, Rosenberg G, Pugh C, Kin C. Physiologic readiness and subjective workload of performing operations: a prospective observational study of attending and trainee surgeons. Am J Surg. 2025;241:116175. doi:10.1016/j.amjsurg.2024.116175
A36: 32 | B36: Norful et al | C36: 2025 | D36: Exploring longitudinal physiologic stress measurement and sleep quality interventions to improve psychological well-being in nurses: a pilot study | E36: Health Psychol Behav Med | F36: USA* | G36: Nurses | H36: 25 | I36: 0.84 | J36: Pilot pre–post trial, 8 weeks (sleep kit from week 4) | K36: Intervention / quasi-experimental | L36: Stress, burnout and depressive symptom surveys | M36: Self-reported sleep quality and latency; Oura sleep | N36: Oura HRV | O36: Oura ring | P36: Self-reported sleep latency improved (p = 0.03). No significant change in Oura physiological measures or depressive symptoms. | Q36: Small pilot; no control group. | R36: Shows 8 weeks of Oura monitoring is feasible in a mostly female sample. | S36: Wearable Device Studies | T36: Y | U36: Y | V36: Y | W36: Y | Z36: 40370681 | AA36: 10.1080/21642850.2025.2503376 | AB36: Norful AA, de Jacq K, Zhao J, et al. Exploring longitudinal physiologic stress measurement and sleep quality interventions to improve psychological well-being in nurses: a pilot study. Health Psychol Behav Med. 2025;13(1):2503376. doi:10.1080/21642850.2025.2503376
A37: 33 | B37: Rosenbach et al | C37: 2025 | D37: Assessing stress level scores against wearables-driven physiological measurements | E37: Stress Health | F37: Israel* | G37: Adults in a laboratory study | H37: 60 (after a 29-person pilot) | I37: NR | J37: Laboratory validation (rest vs mental stress tasks) | K37: Device validation | L37: Self-reported stress | M37: — | N37: Heart rate, HRV (RMSSD, SD2/SD1, HF power), Garmin stress score | O37: Garmin Vivosmart 4 vs Polar H10 chest strap | P37: Garmin stress score differed between rest and stress and correlated with heart rate and RMSSD, but only marginally predicted self-reported stress. Heart rate was the strongest predictor. Responses were influenced by sex. | Q37: Laboratory tasks, not everyday stress. | R37: Garmin's stress score should not replace raw heart rate and HRV. | S37: Wearable Device Studies | V37: Y | W37: Y | X37: Y | Z37: 41292097 | AA37: 10.1002/smi.70125 | AB37: Rosenbach H, Itzkovitch A, Gidron Y, Schonberg T. Assessing stress level scores against wearables-driven physiological measurements. Stress Health. 2025;41(6):e70125. doi:10.1002/smi.70125
A38: 34 | B38: Agarwal et al | C38: 2024 | D38: Investigating the feasibility of using a wearable device to measure physiologic health data in emergency nurses and residents: observational cohort study | E38: JMIR Form Res | F38: USA* | G38: Emergency medicine residents and nurses | H38: 20 | I38: NR | J38: Pilot feasibility cohort, 6 weeks | K38: Longitudinal / cohort | L38: Professional Fulfillment Index (workplace exhaustion, interpersonal disengagement); anxiety and depression | M38: WHOOP sleep | N38: WHOOP HRV and recovery | O38: WHOOP band | P38: Only 10 of 20 used the device consistently; participants preferred more common wearables such as Apple Watch or Fitbit. At baseline: moderate workplace exhaustion and low professional fulfillment. | Q38: Very small; feasibility only. | R38: Adherence warning: choose a familiar device and plan for drop-off. | S38: Wearable Device Studies | T38: Y | U38: Y | V38: Y | W38: Y | Z38: 38386373 | AA38: 10.2196/51569 | AB38: Agarwal AK, Gonzales R, Scott K, Merchant R. Investigating the feasibility of using a wearable device to measure physiologic health data in emergency nurses and residents: observational cohort study. JMIR Form Res. 2024;8:e51569. doi:10.2196/51569
A39: 35 | B39: Wilton et al | C39: 2024 | D39: The Burnout PRedictiOn Using Wearable aNd ArtIficial IntelligEnce (BROWNIE) study: a decentralized digital health protocol to predict burnout in registered nurses | E39: BMC Nurs | F39: USA* | G39: Registered nurses (planned) | H39: 360 planned (3 cohorts) | I39: NR | J39: Study protocol, 1 year, decentralized | K39: Other | L39: Baseline and quarterly psychological and workplace surveys | M39: Smartwatch sleep data | N39: Smartwatch heart rate | O39: Consumer smartwatch (brand not named in abstract) | P39: Protocol only, no results yet. Aims to predict burnout with AI from smartwatch and hospital data. | Q39: No results; nurses only. | R39: Shows the field is moving toward wearable-based burnout prediction. | S39: Wearable Device Studies | T39: Y | U39: Y | V39: Y | W39: Y | Z39: 38347557 | AA39: 10.1186/s12912-024-01711-8 | AB39: Wilton AR, Sheffield K, Wilkes Q, et al. The Burnout PRedictiOn Using Wearable aNd ArtIficial IntelligEnce (BROWNIE) study: a decentralized digital health protocol to predict burnout in registered nurses. BMC Nurs. 2024;23(1):114. doi:10.1186/s12912-024-01711-8
A40: 36 | B40: Hirten et al | C40: 2023 | D40: A machine learning approach to determine resilience utilizing wearable device data: analysis of an observational cohort | E40: JAMIA Open | F40: USA (New York City, 7 hospitals) | G40: Healthcare workers (Warrior Watch Study) | H40: 329 | I40: 0.629 | J40: Secondary analysis of a prospective cohort | K40: Longitudinal / cohort | L40: Resilience (CD-RISC-2), optimism, emotional support; no burnout measure | M40: — | N40: Passively collected Apple Watch physiological data | O40: Apple Watch | P40: Machine learning on wearable data predicted high vs low resilience only weakly (AUC 0.60); a composite positive-psychology score reached AUC 0.65. | Q40: Post hoc analysis; resilience, not burnout. | R40: Wearable data alone only weakly predicts psychological states. | S40: Wearable Device Studies | V40: Y | W40: Y | Z40: 37143859 | AA40: 10.1093/jamiaopen/ooad029 | AB40: Hirten RP, Suprun M, Danieletto M, et al. A machine learning approach to determine resilience utilizing wearable device data: analysis of an observational cohort. JAMIA Open. 2023;6(2):ooad029. doi:10.1093/jamiaopen/ooad029
...

Sheet Summary
A1: Summary of the Literature Matrix
A2: All counts are formulas that read the Literature Matrix sheet, so they update if you edit it.
A4: Overview | B4: Count | C4: % of sources
A5: Total sources | B5: =COUNTA('Literature Matrix'!$A$5:$A$45) -> 41
A6: Sources with ≥50% women (where reported) | B6: =COUNTIF('Literature Matrix'!$I$5:$I$45,">=0.5") -> 12 | C6: =IF($B$5=0,0,B6/$B$5) -> 0.29268293
A7: Women-only samples or reviews | B7: =COUNTIF('Literature Matrix'!$I$5:$I$45,1) -> 2 | C7: =IF($B$5=0,0,B7/$B$5) -> 0.048780488
A8: Sources where % women is not reported in the abstract (NR) | B8: =COUNTIF('Literature Matrix'!$I$5:$I$45,"NR") -> 17 | C8: =IF($B$5=0,0,B8/$B$5) -> 0.41463415
A9: Average % women (studies that report it) | B9: =IFERROR(AVERAGE('Literature Matrix'!$I$5:$I$45),0) -> 0.65742661
A11: By publication year | B11: Count | C11: % of sources
A12: 2021 | B12: =COUNTIF('Literature Matrix'!$C$5:$C$45,2021) -> 4 | C12: =IF($B$5=0,0,B12/$B$5) -> 0.097560976
A13: 2022 | B13: =COUNTIF('Literature Matrix'!$C$5:$C$45,2022) -> 4 | C13: =IF($B$5=0,0,B13/$B$5) -> 0.097560976
A14: 2023 | B14: =COUNTIF('Literature Matrix'!$C$5:$C$45,2023) -> 6 | C14: =IF($B$5=0,0,B14/$B$5) -> 0.14634146
A15: 2024 | B15: =COUNTIF('Literature Matrix'!$C$5:$C$45,2024) -> 6 | C15: =IF($B$5=0,0,B15/$B$5) -> 0.14634146
A16: 2025 | B16: =COUNTIF('Literature Matrix'!$C$5:$C$45,2025) -> 9 | C16: =IF($B$5=0,0,B16/$B$5) -> 0.2195122
A17: 2026 | B17: =COUNTIF('Literature Matrix'!$C$5:$C$45,2026) -> 12 | C17: =IF($B$5=0,0,B17/$B$5) -> 0.29268293
A18: Check: total | B18: =SUM(B12:B17) -> 41 | C18: =IF($B$5=0,0,B18/$B$5) -> 1
A20: By design type | B20: Count | C20: % of sources
A21: Review | B21: =COUNTIF('Literature Matrix'!$K$5:$K$45,"Review") -> 8 | C21: =IF($B$5=0,0,B21/$B$5) -> 0.19512195
A22: Cross-sectional | B22: =COUNTIF('Literature Matrix'!$K$5:$K$45,"Cross-sectional") -> 6 | C22: =IF($B$5=0,0,B22/$B$5) -> 0.14634146
A23: Longitudinal / cohort | B23: =COUNTIF('Literature Matrix'!$K$5:$K$45,"Longitudinal / cohort") -> 12 | C23: =IF($B$5=0,0,B23/$B$5) -> 0.29268293
A24: Daily diary / experience sampling | B24: =COUNTIF('Literature Matrix'!$K$5:$K$45,"Daily diary / experience sampling") -> 2 | C24: =IF($B$5=0,0,B24/$B$5) -> 0.048780488
A25: Intervention / quasi-experimental | B25: =COUNTIF('Literature Matrix'!$K$5:$K$45,"Intervention / quasi-experimental") -> 4 | C25: =IF($B$5=0,0,B25/$B$5) -> 0.097560976
A26: Device validation | B26: =COUNTIF('Literature Matrix'!$K$5:$K$45,"Device validation") -> 4 | C26: =IF($B$5=0,0,B26/$B$5) -> 0.097560976
A27: Measure validation | B27: =COUNTIF('Literature Matrix'!$K$5:$K$45,"Measure validation") -> 2 | C27: =IF($B$5=0,0,B27/$B$5) -> 0.048780488
A28: Other | B28: =COUNTIF('Literature Matrix'!$K$5:$K$45,"Other") -> 3 | C28: =IF($B$5=0,0,B28/$B$5) -> 0.073170732
A29: Check: total | B29: =SUM(B21:B28) -> 41 | C29: =IF($B$5=0,0,B29/$B$5) -> 1
A31: Variables covered | B31: Count | C31: % of sources
A32: Burnout measured | B32: =COUNTIF('Literature Matrix'!$T$5:$T$45,"Y") -> 20 | C32: =IF($B$5=0,0,B32/$B$5) -> 0.48780488
A33: Sleep measured | B33: =COUNTIF('Literature Matrix'!$U$5:$U$45,"Y") -> 21 | C33: =IF($B$5=0,0,B33/$B$5) -> 0.51219512
A34: HRV / RHR measured | B34: =COUNTIF('Literature Matrix'!$V$5:$V$45,"Y") -> 23 | C34: =IF($B$5=0,0,B34/$B$5) -> 0.56097561
A35: Consumer wearable | B35: =COUNTIF('Literature Matrix'!$W$5:$W$45,"Y") -> 23 | C35: =IF($B$5=0,0,B35/$B$5) -> 0.56097561
A36: Women / sex results | B36: =COUNTIF('Literature Matrix'!$X$5:$X$45,"Y") -> 12 | C36: =IF($B$5=0,0,B36/$B$5) -> 0.29268293
A37: Students | B37: =COUNTIF('Literature Matrix'!$Y$5:$Y$45,"Y") -> 9 | C37: =IF($B$5=0,0,B37/$B$5) -> 0.2195122
A39: Combinations (where the gaps are) | B39: Count | C39: % of sources
A40: Burnout + sleep | B40: =COUNTIFS('Literature Matrix'!$T$5:$T$45,"Y",'Literature Matrix'!$U$5:$U$45,"Y") -> 10 | C40: =IF($B$5=0,0,B40/$B$5) -> 0.24390244
A41: Burnout + HRV/RHR | B41: =COUNTIFS('Literature Matrix'!$T$5:$T$45,"Y",'Literature Matrix'!$V$5:$V$45,"Y") -> 9 | C41: =IF($B$5=0,0,B41/$B$5) -> 0.2195122
A42: Burnout + sleep + HRV/RHR | B42: =COUNTIFS('Literature Matrix'!$T$5:$T$45,"Y",'Literature Matrix'!$U$5:$U$45,"Y",'Literature Matrix'!$V$5:$V$45,"Y") -> 4 | C42: =IF($B$5=0,0,B42/$B$5) -> 0.097560976
A43: Burnout + sleep + HRV/RHR + consumer wearable | B43: =COUNTIFS('Literature Matrix'!$T$5:$T$45,"Y",'Literature Matrix'!$U$5:$U$45,"Y",'Literature Matrix'!$V$5:$V$45,"Y",'Literature Matrix'!$W$5:$W$45,"Y") -> 4 | C43: =IF($B$5=0,0,B43/$B$5) -> 0.097560976
A44: …and reports results for women / by sex | B44: =COUNTIFS('Literature Matrix'!$T$5:$T$45,"Y",'Literature Matrix'!$U$5:$U$45,"Y",'Literature Matrix'!$V$5:$V$45,"Y",'Literature Matrix'!$W$5:$W$45,"Y",'Literature Matrix'!$X$5:$X$45,"Y") -> 0 | C44: =IF($B$5=0,0,B44/$B$5) -> 0
A45: Burnout + consumer wearable + students | B45: =COUNTIFS('Literature Matrix'!$T$5:$T$45,"Y",'Literature Matrix'!$W$5:$W$45,"Y",'Literature Matrix'!$Y$5:$Y$45,"Y") -> 0 | C45: =IF($B$5=0,0,B45/$B$5) -> 0
...
