Workbook

Sheet Numbers check
A1: MRKH scoping review: which numbers are real
A2: Checked against the March 29–30, 2026 chats where the search results were screened. Pink = estimate or unknown source, green = real count.
A4: Step | B4: In your abstract | C4: Status | D4: Where it came from | E4: What to do before APHA
A5: Records identified | B5: 516 | C5: Real count | D5: Sum of your four exports (see the database table below). | E5: Keep.
A6: Duplicates removed | B6: 155 | C6: Estimate | D6: 516 minus 361. | E6: Deduplicate the four exports in Zotero, EndNote or Rayyan and record the real number.
A7: Records screened after deduplication | B7: 361 | C7: Estimate | D7: Calculated in the March 29 chat as 70% of 516 (an assumed 30% overlap). No deduplication was ever run. | E7: Replace with the real deduplicated count.
A8: Studies included | B8: 34 | C8: Estimate | D8: "About 45" (itself an estimate) minus the 11 studies removed on March 30. The screened-in lists actually hold 61 unique studies (see live counts below). | E8: Finish full-text checks in the tracker; the final count is the number of rows marked Include.
A9: Domain counts: 26, 22, 19, 17, 21, 18 | B9: 26 / 22 / 19 / 17 / 21 / 18 | C9: Source not found | D9: First appear in the abstract file you brought to Claude on March 30. No charting of the included studies exists in our chats. | E9: Mark each included study in the six domain columns; the counts below update automatically.
A12: Records in each export (read from your files in the March 29 chat)
A13: PubMed/MEDLINE | B13: 146 | C13: Record count of the export file
A14: Scopus | B14: 143 | C14: Record count of the export file
A15: PsycINFO (EBSCO) | B15: 20 | C15: Record count of the export file
A16: CINAHL (EBSCO) | B16: 207 | C16: Record count of the export file
A17: Total identified | B17: =SUM(B13:B16) -> 516
A19: Live counts from the tracker
A20: Unique studies screened in across the four databases | B20: =COUNTA('Screened-in studies'!B5:B65) -> 61 | C20: Titles matched by hand across the four March lists
A21: Removed on the March 30 re-check | B21: =COUNTIF('Screened-in studies'!I5:I65,"Removed*") -> 11 | C21: Case reports, French-language papers, mixed populations, one editorial
A22: Kept after March 30 | B22: =COUNTIF('Screened-in studies'!I5:I65,"Kept*") -> 50
A23: of which reviews or commentary (outside your primary-research criterion) | B23: =COUNTIFS('Screened-in studies'!I5:I65,"Kept*",'Screened-in studies'!K5:K65,"Review*")+COUNTIFS('Screened-in studies'!I5:I65,"Kept*",'Screened-in studies'!K5:K65,"Commentary*") -> 7
A24: of which need another check (language, mixed sample, conference paper, etc.) | B24: =COUNTIFS('Screened-in studies'!I5:I65,"Kept*",'Screened-in studies'!K5:K65,"<>")-B23 -> 8
A25: Final included (your decisions in the tracker) | B25: =COUNTIF('Screened-in studies'!N5:N65,"Include") -> 0 | C25: Starts at 0 and fills in as you mark studies Include
A27: Domain counts among included studies
A28: Domain | B28: Studies (n) | C28: % of included
A29: Depression / anxiety | B29: =COUNTIFS('Screened-in studies'!N5:N65,"Include",'Screened-in studies'!R5:R65,"Y") -> 0 | C29: =IF($B$25=0,"",B29/$B$25)
A30: QoL / body image | B30: =COUNTIFS('Screened-in studies'!N5:N65,"Include",'Screened-in studies'!S5:S65,"Y") -> 0 | C30: =IF($B$25=0,"",B30/$B$25)
A31: Psychosexual / relational | B31: =COUNTIFS('Screened-in studies'!N5:N65,"Include",'Screened-in studies'!T5:T65,"Y") -> 0 | C31: =IF($B$25=0,"",B31/$B$25)
A32: Psychological distress | B32: =COUNTIFS('Screened-in studies'!N5:N65,"Include",'Screened-in studies'!U5:U65,"Y") -> 0 | C32: =IF($B$25=0,"",B32/$B$25)
A33: Coping mechanisms | B33: =COUNTIFS('Screened-in studies'!N5:N65,"Include",'Screened-in studies'!V5:V65,"Y") -> 0 | C33: =IF($B$25=0,"",B33/$B$25)
A34: Healthcare system gaps | B34: =COUNTIFS('Screened-in studies'!N5:N65,"Include",'Screened-in studies'!W5:W65,"Y") -> 0 | C34: =IF($B$25=0,"",B34/$B$25)
A36: How to use the tracker
A37: 1. Open the "Screened-in studies" tab. Only the yellow columns (M to W) are for you to fill in; the grey columns record what was decided in March.
A38: 2. For each study: read the full text, put Y in "Full text checked", choose Include or Exclude, and give a reason if excluded.
A39: 3. For every Include, put Y under each domain the study reports. The domain counts above then give your real n values.
A40: 4. Start with the red "Check before counting" notes: reviews and commentary fall outside your primary-research criterion.
A41: 5. Example row (format only, not a real study): Full text checked = Y · Final decision = Include · Country = Denmark · Study design = Qualitative interviews · QoL / body image = Y · Coping mechanisms = Y

Sheet Screened-in studies
A1: MRKH scoping review: studies screened in from your four database exports (March 29, 2026)
A2: Grey columns come from the March screening. Yellow columns are yours to fill in after reading each full text. Titles are as recorded in that screening (shortened); confirm exact titles and citations from your exports.
A4: # | B4: Title (as recorded in March screening) | C4: Year | D4: Scopus | E4: PubMed | F4: PsycINFO | G4: CINAHL | H4: Found in (n) | I4: March status | J4: March notes | K4: Check before counting | L4: Background ref # | M4: Full text checked (Y/N) | N4: Final decision (Include/Exclude) | O4: Reason if excluded | P4: Country | Q4: Study design | R4: Depression / anxiety | S4: QoL / body image | T4: Psychosexual / relational | U4: Psychological distress | V4: Coping mechanisms | W4: Healthcare system gaps
A5: 1 | B5: Psychological impact of neovagina creation and uterus transplantation in MRKH: a narrative review | C5: 2024 | D5: Y | E5: Y | G5: Y | H5: =COUNTIF(D5:G5,"Y") -> 3 | I5: Kept after 30 Mar re-check | J5: Review | K5: Review article: your criteria include primary studies only
A6: 2 | B6: The need to integrate mental health treatment into the care of MRKH | C6: 2025 | D6: Y | G6: Y | H6: =COUNTIF(D6:G6,"Y") -> 2 | I6: Kept after 30 Mar re-check | J6: Short survey. Davoudian & Hills, F S Rep | K6: Commentary-type article, not primary research | L6: 9
A7: 3 | B7: Self-esteem, depression, anxiety and sexual function in MRKH with neovagina | C7: 2024 | D7: Y | E7: Y | G7: Y | H7: =COUNTIF(D7:G7,"Y") -> 3 | I7: Kept after 30 Mar re-check
A8: 4 | B8: Psychological correlates of sexual self-esteem in young women with MRKH | C8: 2022 | D8: Y | E8: Y | F8: Y | G8: Y | H8: =COUNTIF(D8:G8,"Y") -> 4 | I8: Kept after 30 Mar re-check
A9: 5 | B9: Study on depressive symptoms in patients with MRKH: 141 cases | C9: 2020 | D9: Y | G9: Y | H9: =COUNTIF(D9:G9,"Y") -> 2 | I9: Kept after 30 Mar re-check
A10: 6 | B10: Prevalence of anxiety and depression in women with MRKH in Malaysia | C10: 2025 | D10: Y | E10: Y | G10: Y | H10: =COUNTIF(D10:G10,"Y") -> 3 | I10: Kept after 30 Mar re-check | J10: CINAHL lists 2026
A11: 7 | B11: Sexual function and quality of life after neovagina creation in MRKH | C11: 2020 | D11: Y | G11: Y | H11: =COUNTIF(D11:G11,"Y") -> 2 | I11: Kept after 30 Mar re-check
A12: 8 | B12: Sexual experience before treatment for vaginal agenesis | C12: 2019 | D12: Y | G12: Y | H12: =COUNTIF(D12:G12,"Y") -> 2 | I12: Kept after 30 Mar re-check | J12: Confirmed 30 Mar: 137 women, most with MRKH
A13: 9 | B13: Evaluation of sexual function outcomes in Rokitansky syndrome: systematic review | C13: 2023 | D13: Y | E13: Y | H13: =COUNTIF(D13:G13,"Y") -> 2 | I13: Kept after 30 Mar re-check | J13: Review | K13: Review article: your criteria include primary studies only
A14: 10 | B14: Sexual and psychosocial outcome after neovaginoplasty in MRKH: case-control study | C14: 2022 | D14: Y | E14: Y | G14: Y | H14: =COUNTIF(D14:G14,"Y") -> 3 | I14: Kept after 30 Mar re-check | J14: Note. Scopus lists it as a Note
A15: 11 | B15: Psychological and emotional profiles of Australian uterine transplant potential recipients | C15: 2025 | D15: Y | E15: Y | G15: Y | H15: =COUNTIF(D15:G15,"Y") -> 3 | I15: Kept after 30 Mar re-check | J15: Confirmed 30 Mar: MRKH is the main indication
A16: 12 | B16: Psychiatric aspects of differences of sex development | C16: 2025 | D16: Y | H16: =COUNTIF(D16:G16,"Y") -> 1 | I16: Kept after 30 Mar re-check | J16: Note | K16: DSD broadly: confirm MRKH findings are reported separately and that it is primary research
A17: 13 | B17: Long-term results of sexual function and body image after vaginoplasty in MRKH | C17: 2024 | D17: Y | E17: Y | G17: Y | H17: =COUNTIF(D17:G17,"Y") -> 3 | I17: Kept after 30 Mar re-check
A18: 14 | B18: International experiences with vaginal lengthening in Müllerian agenesis: mixed-methods study | C18: 2023 | D18: Y | E18: Y | G18: Y | H18: =COUNTIF(D18:G18,"Y") -> 3 | I18: Kept after 30 Mar re-check
A19: 15 | B19: "Don't give up, advocate for yourself": healthcare experiences of people with MRKH | C19: 2025 | D19: Y | G19: Y | H19: =COUNTIF(D19:G19,"Y") -> 2 | I19: Kept after 30 Mar re-check | J19: Marshall et al., J Pediatr Adolesc Gynecol | L19: 8
A20: 16 | B20: How does the experience of medical encounters with MRKH impact women in Africa? | C20: 2022 | D20: Y | H20: =COUNTIF(D20:G20,"Y") -> 1 | I20: Kept after 30 Mar re-check
A21: 17 | B21: Impact of MRKH syndrome on psychology, quality of life, and sexual life: systematic review | C21: 2022 | D21: Y | E21: Y | G21: Y | H21: =COUNTIF(D21:G21,"Y") -> 3 | I21: Kept after 30 Mar re-check | J21: Review. Tsarna et al., Children (Basel) | K21: Review article: your criteria include primary studies only | L21: 2
A22: 18 | B22: Experiences of vaginal lengthening treatment and sexual well-being in MRKH: interview study | C22: 2024 | D22: Y | E22: Y | G22: Y | H22: =COUNTIF(D22:G22,"Y") -> 3 | I22: Kept after 30 Mar re-check | J22: Jensen et al., BJOG | L22: 5
A23: 19 | B23: Low self-esteem of women with MRKH | C23: 2019 | D23: Y | H23: =COUNTIF(D23:G23,"Y") -> 1 | I23: Kept after 30 Mar re-check
A24: 20 | B24: Psychosexual education on sexual function and genital self-image in Rokitansky syndrome: RCT | C24: 2022 | D24: Y | E24: Y | G24: Y | H24: =COUNTIF(D24:G24,"Y") -> 3 | I24: Kept after 30 Mar re-check
A25: 21 | B25: A life course perspective on MRKH: women's experiences and negotiations | C25: 2024 | D25: Y | E25: Y | F25: Y | G25: Y | H25: =COUNTIF(D25:G25,"Y") -> 4 | I25: Kept after 30 Mar re-check | J25: Jensen et al., Disabil Rehabil | L25: 4
A26: 22 | B26: Issues of identity, perceptions and isolation in MRKH: interpretative phenomenological analysis | C26: 2024 | D26: Y | E26: Y | G26: Y | H26: =COUNTIF(D26:G26,"Y") -> 3 | I26: Kept after 30 Mar re-check | J26: Gilfillan & Carter, J Health Psychol | L26: 6
A27: 23 | B27: Psychological evaluation of candidates for uterus transplantation (French trial) | C27: 2025 | D27: Y | E27: Y | G27: Y | H27: =COUNTIF(D27:G27,"Y") -> 3 | I27: Kept after 30 Mar re-check | J27: Confirmed 30 Mar: all participants have MRKH
A28: 24 | B28: Effectiveness of non-surgical interventions to improve health and well-being in women with MRKH | C28: 2024 | D28: Y | E28: Y | F28: Y | G28: Y | H28: =COUNTIF(D28:G28,"Y") -> 4 | I28: Kept after 30 Mar re-check | J28: Review | K28: Review article: your criteria include primary studies only
A29: 25 | B29: "I felt like a woman": phenomenological study of disease-related experiences in MRKH | C29: 2025 | D29: Y | E29: Y | G29: Y | H29: =COUNTIF(D29:G29,"Y") -> 3 | I29: Kept after 30 Mar re-check | J29: Güner et al., J Health Psychol | L29: 7
A30: 26 | B30: From engulfment to enrichment: illness representations, self-concept and adjustment in MRKH | C30: 2020 | D30: Y | G30: Y | H30: =COUNTIF(D30:G30,"Y") -> 2 | I30: Kept after 30 Mar re-check
A31: 27 | B31: Urogynecological and sexual functions after Vecchietti surgery | C31: 2019 | D31: Y | H31: =COUNTIF(D31:G31,"Y") -> 1 | I31: Kept after 30 Mar re-check | J31: Screened in from Scopus; the CINAHL copy was excluded as mainly surgical | K31: Conflicting March decisions: decide include or exclude
A32: 28 | B32: Sexual, relational and psychological functioning in male partners of women with MRKH | C32: 2025 | D32: Y | E32: Y | G32: Y | H32: =COUNTIF(D32:G32,"Y") -> 3 | I32: Kept after 30 Mar re-check | K32: Participants are male partners, not people with MRKH: check against your population criterion
A33: 29 | B33: Perception of having children through surrogacy among individuals with MRKH in Vietnam | C33: 2024 | D33: Y | E33: Y | G33: Y | H33: =COUNTIF(D33:G33,"Y") -> 3 | I33: Kept after 30 Mar re-check
A34: 30 | B34: Psychological and personality assessment in candidates for uterus transplantation | C34: 2020 | D34: Y | H34: =COUNTIF(D34:G34,"Y") -> 1 | I34: Kept after 30 Mar re-check | K34: Transplant candidates: confirm MRKH results are reported separately
A35: 31 | B35: The sexuality of adolescents and young women with MRKH: qualitative study | C35: 2021 | D35: Y | E35: Y | F35: Y | G35: Y | H35: =COUNTIF(D35:G35,"Y") -> 4 | I35: Kept after 30 Mar re-check
A36: 32 | B36: From avoidance to empowerment: coping strategies in MRKH after McIndoe reconstruction | C36: 2025 | D36: Y | E36: Y | G36: Y | H36: =COUNTIF(D36:G36,"Y") -> 3 | I36: Kept after 30 Mar re-check | J36: CINAHL lists 2026; Güner et al. (not verified in March)
A37: 33 | B37: Understanding the impact of MRKH on sexual wellbeing: qualitative study | C37: 2026 | D37: Y | E37: Y | G37: Y | H37: =COUNTIF(D37:G37,"Y") -> 3 | I37: Kept after 30 Mar re-check
A38: 34 | B38: Illness experience and (unmet) needs of women with MRKH: qualitative analysis of an online forum | C38: 2026 | D38: Y | E38: Y | F38: Y | G38: Y | H38: =COUNTIF(D38:G38,"Y") -> 4 | I38: Kept after 30 Mar re-check | J38: PsycINFO lists 2024
A39: 35 | B39: Sexuality in women with MRKH | C39: 2021 | D39: Y | G39: Y | H39: =COUNTIF(D39:G39,"Y") -> 2 | I39: Kept after 30 Mar re-check | J39: CINAHL record marked Czech | K39: Check language (English-only criterion)
A40: 36 | B40: Burden of MRKH: effect of an intervention to support surgical neovaginal placement (Belastung von Betroffenen mit MRKH-Syndrom) | C40: 2022 | D40: Y | E40: Y | F40: Y | G40: Y | H40: =COUNTIF(D40:G40,"Y") -> 4 | I40: Kept after 30 Mar re-check | J40: German title in PsycINFO | K40: Check language (English-only criterion)
A41: 37 | B41: Sexual satisfaction in MRKH after surgical and non-surgical techniques: systematic review | C41: 2019 | D41: Y | G41: Y | H41: =COUNTIF(D41:G41,"Y") -> 2 | I41: Kept after 30 Mar re-check | J41: Review | K41: Review article: your criteria include primary studies only
...

Sheet Background references
A1: Background references verified in the March 2026 chat (AMA style)
A2: Each was checked against PubMed or the publisher in March 2026. They were not re-checked on Sept 29 because PubMed rate-limited the requests. Italicize journal names when you paste them into Word.
A4: # | B4: AMA citation | C4: DOI | D4: PMID | E4: Used for | F4: Note
A5: 1 | B5: Herlin MK, Petersen MB, Brännström M. Mayer-Rokitansky-Küster-Hauser (MRKH) syndrome: a comprehensive update. Orphanet J Rare Dis. 2020;15(1):214. doi:10.1186/s13023-020-01491-9 | C5: 10.1186/s13023-020-01491-9 | D5: 32819397 | E5: Background: prevalence, clinical features
A6: 2 | B6: Tsarna E, Eleftheriades A, Eleftheriades M, Kalampokas E, Liakopoulou MK, Christopoulos P. The impact of Mayer-Rokitansky-Küster-Hauser syndrome on psychology, quality of life, and sexual life of patients: a systematic review. Children (Basel). 2022;9(4):484. doi:10.3390/children9040484 | C6: 10.3390/children9040484 | D6: 35455528 | E6: Background: psychological burden | F6: Also in the tracker (#17), flagged as a review
A7: 3 | B7: Weijenborg PTM, Kluivers KB, Dessens AB, Kate-Booij MJ, Both S. Sexual functioning, sexual esteem, genital self-image and psychological and relational functioning in women with Mayer-Rokitansky-Küster-Hauser syndrome: a case-control study. Hum Reprod. 2019;34(9):1661-1673. doi:10.1093/humrep/dez130 | C7: 10.1093/humrep/dez130 | D7: 31418785 | E7: Psychosexual and relational outcomes | F7: Also in the tracker (#44)
A8: 4 | B8: Jensen AH, Herlin MK, Vogel I, et al. A life course perspective on Mayer-Rokitansky-Küster-Hauser syndrome: women's experiences and negotiations of living with an underdeveloped uterus and vagina. Disabil Rehabil. 2024;46:1130-1140. doi:10.1080/09638288.2023.2194463 | C8: 10.1080/09638288.2023.2194463 | E8: Coping and adaptation | F8: Add the issue number and PMID. Also in the tracker (#21)
A9: 5 | B9: Jensen AH, Lou S, Vogel I, Trolle B, Herlin MK. Experiences of vaginal lengthening treatment and sexual wellbeing in women with Mayer-Rokitansky-Küster-Hauser (MRKH) syndrome: an interview study. BJOG. 2024. doi:10.1111/1471-0528.17912 | C9: 10.1111/1471-0528.17912 | D9: 39039723 | E9: Sexual well-being, treatment experience | F9: Was online-ahead-of-print: add volume and pages. Also in the tracker (#18)
A10: 6 | B10: Gilfillan R, Carter P. Issues of identity, perceptions and isolation: an interpretative phenomenological analysis of women's experience of Mayer-Rokitansky-Küster-Hauser (MRKH) syndrome. J Health Psychol. 2024;29(3):200-212. doi:10.1177/13591053231199253 | C10: 10.1177/13591053231199253 | D10: 37771134 | E10: Identity, isolation, coping | F10: Also in the tracker (#22)
A11: 7 | B11: Güner P, Ulukaya T, Pehlivan Sarıbudak T. "I felt like a woman": a phenomenological qualitative study of disease-related experiences in Mayer-Rokitansky-Küster-Hauser syndrome (MRKH syndrome). J Health Psychol. 2025;30(11):3137-3152. doi:10.1177/13591053241305941 | C11: 10.1177/13591053241305941 | D11: 40955819 | E11: Emotional, cognitive and spiritual coping | F11: Also in the tracker (#25)
A12: 8 | B12: Marshall N, Rajesh Z, Hunker K, et al. "Don't give up, advocate for yourself": a pilot study examining healthcare experiences of people with Mayer Rokitansky Küster Hauser syndrome. J Pediatr Adolesc Gynecol. 2025;38(2):167-173. doi:10.1016/j.jpag.2024.12.001 | C12: 10.1016/j.jpag.2024.12.001 | D12: 39653110 | E12: Healthcare system gaps | F12: Also in the tracker (#15)
A13: 9 | B13: Davoudian T, Hills E. The need to integrate mental health treatment into the care of Mayer-Rokitansky-Küster-Hauser. F S Rep. 2025;6(2):116-119. doi:10.1016/j.xfre.2025.03.008 | C13: 10.1016/j.xfre.2025.03.008 | D13: 40620385 | E13: Mental health integration in care | F13: Also in the tracker (#2), flagged as commentary
A14: 10 | B14: American College of Obstetricians and Gynecologists. Committee Opinion No. 728: Müllerian agenesis: diagnosis, management, and treatment. Obstet Gynecol. 2018;131(1):e35-e42. doi:10.1097/AOG.0000000000002458 | C14: 10.1097/AOG.0000000000002458 | D14: 29266078 | E14: Clinical guidance: counseling and peer support
A15: 11 | B15: Arksey H, O'Malley L. Scoping studies: towards a methodological framework. Int J Soc Res Methodol. 2005;8(1):19-32. doi:10.1080/1364557032000119616 | C15: 10.1080/1364557032000119616 | E15: Methods: scoping review framework
A16: 12 | B16: Peters MDJ, Marnie C, Tricco AC, et al. Updated methodological guidance for the conduct of scoping reviews. JBI Evid Synth. 2020;18(10):2119-2126. doi:10.11124/JBIES-20-00167 | C16: 10.11124/JBIES-20-00167 | D16: 33038124 | E16: Methods: JBI guidance
A17: 13 | B17: Tricco AC, Lillie E, Zarin W, et al. PRISMA extension for scoping reviews (PRISMA-ScR): checklist and explanation. Ann Intern Med. 2018;169(7):467-473. doi:10.7326/M18-0850 | C17: 10.7326/M18-0850 | D17: 30178033 | E17: Methods: reporting guideline
B19: Also named in your original draft but never verified in March: Song 2020, Chen 2020, Stepanow 2023, Lei 2024. Look these up in PubMed before citing them.
